- 异常处理机制主要回答了三个问题：

  what：异常类型回答了什么被抛出

  where：异常堆栈跟踪回答了在哪抛出

  why：异常信息回答了为什么被抛出

- Error和Exception的区别：Throwable为java异常体系的顶级父类

  ![1558902950535](http://weiguo-1303915920.cos.ap-nanjing.myqcloud.com/90ab6626a6f5cf3a7d9cb8948b3d6b7d.png)

  ​		Error：程序无法处理的系统错误，编译器不做检查

  ​		Exception：程序可以处理的异常，捕获后可能恢复

  ​		总结：前者是程序无法处理的错误，后者是可以处理的异常

  ​	从责任角度看：

  1. Error属于JVM需要负担的责任；
2. RuntimeException是程序应该负担的责任；
  3. Checked Exception是Java编译器应该负担的责任。

- RuntimeException（运行时异常又称非检查异常）：不可预知的，程序应当自行避免（如			NullpointerException，ArrayIndexOutOfBoundsException等）

- 非RuntimeException（检查异常）：可预知的，从编译器校验出的异常。（如IOException 文件异常，SQLException SQL数据库错误异常）

![1558905094316](http://weiguo-1303915920.cos.ap-nanjing.myqcloud.com/974bba6ef5cd1d309a27c60c9abda85a.png)

![1558905853685](http://weiguo-1303915920.cos.ap-nanjing.myqcloud.com/0a85ced89db3aed69e7b3c414dc8de07.png)

- **try catch finally 执行顺序**

仅仅在下面4中情况下不会执行finally语句 :

①.如果在try 或catch语句中执行了System.exit(0)。

②.在执行finally之前jvm崩溃了。

③.try语句中执行死循环。

④.电源断电。

当try和catch中有return时，finally仍然会执行；

当finally里面没有return语句时，执行try 和finally语句之后最后再执行return。 

finally是在return后面的表达式运算后执行的（此时并没有返回运算后的值，而是先把要返回的值保存起来，管finally中的代码怎么样，返回的值都不会改变，仍然是之前保存的值），所以函数返回值是在finally执行前确定的；

**经典面试题**

下面题目输出什么？

```java
public static int demo5() {
        try {
            return printX();
        }
        finally {
            System.out.println("finally trumps return... sort of");
        }
    }
    public static int printX() {

        System.out.println("X");
        return 0;
    }
```

输出结果：

```
X
finally trumps return... sort of
0
```

上面这道题目含金量很高，程序顺序执行时先执行printX（）函数，此时得到返回值0并且将0保存到variable中对应的用于保存返回值的区域，此时程序在执行finally语句因为finally语句中没有return语句，所以程序将返回值区域的0返回给上一级函数。